2025-01-07 11:38:34,374 | ERROR | Ошибка
Traceback (most recent call last):
  File "D:\PycharmProjects\new_python_Project\module_12\tests_12_4.py", line 27, in test_run
    r2 = cv.Runner(19,15)
         ^^^^^^^^^^^^^^^^
  File "D:\PycharmProjects\new_python_Project\module_12\code_for_verification.py", line 6, in __init__
    raise TypeError(f'Имя может быть только строкой, передано {type(name).__name__}')
TypeError: Имя может быть только строкой, передано int
2025-01-07 11:38:34,375 | WARNING | Неверный тип данных для объекта Runner
2025-01-07 11:38:34,375 | INFO | "test_run" выполнен успешно
2025-01-07 11:38:34,376 | ERROR | Ошибка
Traceback (most recent call last):
  File "D:\PycharmProjects\new_python_Project\module_12\tests_12_4.py", line 15, in test_walk
    r1 = cv.Runner('Name', -10)
         ^^^^^^^^^^^^^^^^^^^^^^
  File "D:\PycharmProjects\new_python_Project\module_12\code_for_verification.py", line 11, in __init__
    raise ValueError(f'Скорость не может быть отрицательной, сейчас {speed}')
ValueError: Скорость не может быть отрицательной, сейчас -10
2025-01-07 11:38:34,376 | WARNING | Неверная скорость для Runner
2025-01-07 11:38:34,376 | INFO | "test_walk" выполнен успешно
